2024-08-29 11:13:12,860 - ERROR - Database error: no such table: state_populations
2024-08-29 11:13:12,861 - ERROR - An error occurred: no such table: state_populations
Traceback (most recent call last):
  File "predict_price.py", line 93, in <module>
  File "predict_price.py", line 48, in get_population_from_db
sqlite3.OperationalError: no such table: state_populations
2024-08-29 11:26:34,582 - ERROR - Database file 'state_populations.db' not found.
2024-08-29 11:26:34,583 - ERROR - Unexpected error: Database file 'state_populations.db' not found.
2024-08-29 11:26:34,583 - ERROR - An error occurred: Database file 'state_populations.db' not found.
Traceback (most recent call last):
  File "predict_price.py", line 108, in <module>
  File "predict_price.py", line 49, in get_population_from_db
FileNotFoundError: Database file 'state_populations.db' not found.
2024-08-29 11:36:42,027 - ERROR - Database file 'C:\Users\Justi\projects\python\dist\state_populations.db' not found.
2024-08-29 11:36:42,029 - ERROR - Unexpected error: Database file 'C:\Users\Justi\projects\python\dist\state_populations.db' not found.
2024-08-29 11:36:42,030 - ERROR - An error occurred: Database file 'C:\Users\Justi\projects\python\dist\state_populations.db' not found.
Traceback (most recent call last):
  File "predict_price.py", line 109, in <module>
  File "predict_price.py", line 50, in get_population_from_db
FileNotFoundError: Database file 'C:\Users\Justi\projects\python\dist\state_populations.db' not found.
2024-08-29 11:45:12,345 - ERROR - Database error: file is not a database
2024-08-29 11:45:12,346 - ERROR - An error occurred: file is not a database
Traceback (most recent call last):
  File "predict_price.py", line 119, in <module>
  File "predict_price.py", line 66, in get_population_from_db
sqlite3.DatabaseError: file is not a database
2024-08-29 11:56:56,373 - ERROR - An error occurred: State input is required
Traceback (most recent call last):
  File "predict_price.py", line 118, in <module>
ValueError: State input is required
2024-08-29 16:14:27,820 - ERROR - An unexpected error occurred: 'NoneType' object has no attribute 'upper'
Traceback (most recent call last):
  File "predict_price.py", line 145, in <module>
AttributeError: 'NoneType' object has no attribute 'upper'
